Workbook

Sheet analyze
A1: sto/bto | B1: price | C1: short-term max | D1: short-term min | E1: short-term success | F1: STS % | G1: long-term max | H1: short-term min | I1: long-term success | J1: LTS % | K1: =titled!W3 -> goodvolume | L1: =titled!X3 -> rsi | M1: =titled!Y3 -> rsi-1 | N1: =titled!Z3 -> rsi-2 | O1: =titled!AA3 -> rsi-3 | P1: =titled!AB3 -> rsi-4 | Q1: =titled!AC3 -> dvi | R1: =titled!AD3 -> dvi-1 | ... BI1: =titled!BU3 -> vold[50]/M | CA1: drsi | CB1: ddvi | CC1: drs
A7: ='raw data'!D7 -> bto | B7: ='raw data'!F7 -> 9.82 | C7: =MAX('raw data'!G7:P7) -> 9.8 | D7: =MIN('raw data'!H7:Q7) -> 9.725 | E7: =IF($A7="bto",analyze!C7-'raw data'!F7,IF($A7="sto",'raw data'!F7-analyze!D7,0)) -> -0.02 | F7: =IF(B7>0,E7/B7,0) -> -0.0020366599 | G7: =MAX('raw data'!R7:V7) -> 10.085 | H7: =MIN('raw data'!R7:V7) -> 9.7381 | I7: =IF(A7="bto",analyze!G7-B7,IF(A7="sto",B7-analyze!H7,0)) -> 0.265 | J7: =IF(B7>0,I7/B7,0) -> 0.026985743 | K7: ='raw data'!W7 -> 0.1535 | L7: ='raw data'!X7 -> 48.2988 | M7: ='raw data'!Y7 -> 40.023 | N7: ='raw data'!Z7 -> 43.5067 | O7: ='raw data'!AA7 -> 43.5067 | P7: ='raw data'!AB7 -> 39.5063 | Q7: ='raw data'!AC7 -> -1.155 | R7: ='raw data'!AD7 -> -1.2343 | ... BI7: ='raw data'!BU7 -> 368.5387 | CA7: =$L7-$P7 -> 8.7925 | CB7: =$Q7-$U7 -> -0.0478 | CC7: =$X7-$AB7 -> 0.4543
A8: ='raw data'!D8 -> Sell to Close | B8: ='raw data'!F8 -> 9.73 | C8: =MAX('raw data'!G8:P8) -> 38676.417 | D8: =MIN('raw data'!H8:Q8) -> -0.1 | E8: =IF($A8="bto",analyze!C8-'raw data'!F8,IF($A8="sto",'raw data'!F8-analyze!D8,0)) -> 0 | F8: =IF(B8>0,E8/B8,0) -> 0 | G8: =MAX('raw data'!R8:V8) -> 0 | H8: =MIN('raw data'!R8:V8) -> 0 | I8: =IF(A8="bto",analyze!G8-B8,IF(A8="sto",B8-analyze!H8,0)) -> 0 | J8: =IF(B8>0,I8/B8,0) -> 0 | K8: ='raw data'!W8 -> 0 | L8: ='raw data'!X8 -> 0 | M8: ='raw data'!Y8 -> 0 | N8: ='raw data'!Z8 -> 0 | O8: ='raw data'!AA8 -> 0 | P8: ='raw data'!AB8 -> 0 | Q8: ='raw data'!AC8 -> 0 | R8: ='raw data'!AD8 -> 0 | ... BI8: ='raw data'!BU8 -> 0 | CA8: =$L8-$P8 -> 0 | CB8: =$Q8-$U8 -> 0 | CC8: =$X8-$AB8 -> 0
A9: ='raw data'!D9 -> bto | B9: ='raw data'!F9 -> 9.821 | C9: =MAX('raw data'!G9:P9) -> 9.835 | D9: =MIN('raw data'!H9:Q9) -> 9.81 | E9: =IF($A9="bto",analyze!C9-'raw data'!F9,IF($A9="sto",'raw data'!F9-analyze!D9,0)) -> 0.014 | F9: =IF(B9>0,E9/B9,0) -> 0.0014255167 | G9: =MAX('raw data'!R9:V9) -> 10.1419 | H9: =MIN('raw data'!R9:V9) -> 9.771 | I9: =IF(A9="bto",analyze!G9-B9,IF(A9="sto",B9-analyze!H9,0)) -> 0.3209 | J9: =IF(B9>0,I9/B9,0) -> 0.03267488 | K9: ='raw data'!W9 -> 0.4361 | L9: ='raw data'!X9 -> 73.8257 | M9: ='raw data'!Y9 -> 67.8365 | N9: ='raw data'!Z9 -> 66.4443 | O9: ='raw data'!AA9 -> 61.171 | P9: ='raw data'!AB9 -> 58.9742 | Q9: ='raw data'!AC9 -> -1.2664 | R9: ='raw data'!AD9 -> -1.368 | ... BI9: ='raw data'!BU9 -> -116.3051 | CA9: =$L9-$P9 -> 14.8515 | CB9: =$Q9-$U9 -> 0.1996 | CC9: =$X9-$AB9 -> 0.5107
A10: ='raw data'!D10 -> Sell to Close | B10: ='raw data'!F10 -> 9.82 | C10: =MAX('raw data'!G10:P10) -> 38676.465 | D10: =MIN('raw data'!H10:Q10) -> -0.1 | E10: =IF($A10="bto",analyze!C10-'raw data'!F10,IF($A10="sto",'raw data'!F10-analyze!D10,0)) -> 0 | F10: =IF(B10>0,E10/B10,0) -> 0 | G10: =MAX('raw data'!R10:V10) -> 0 | H10: =MIN('raw data'!R10:V10) -> 0 | I10: =IF(A10="bto",analyze!G10-B10,IF(A10="sto",B10-analyze!H10,0)) -> 0 | J10: =IF(B10>0,I10/B10,0) -> 0 | K10: ='raw data'!W10 -> 0 | L10: ='raw data'!X10 -> 0 | M10: ='raw data'!Y10 -> 0 | N10: ='raw data'!Z10 -> 0 | O10: ='raw data'!AA10 -> 0 | P10: ='raw data'!AB10 -> 0 | Q10: ='raw data'!AC10 -> 0 | R10: ='raw data'!AD10 -> 0 | ... BI10: ='raw data'!BU10 -> 0 | CA10: =$L10-$P10 -> 0 | CB10: =$Q10-$U10 -> 0 | CC10: =$X10-$AB10 -> 0
A11: ='raw data'!D11 -> bto | B11: ='raw data'!F11 -> 9.85 | C11: =MAX('raw data'!G11:P11) -> 9.9199 | D11: =MIN('raw data'!H11:Q11) -> 9.85 | E11: =IF($A11="bto",analyze!C11-'raw data'!F11,IF($A11="sto",'raw data'!F11-analyze!D11,0)) -> 0.0699 | F11: =IF(B11>0,E11/B11,0) -> 0.0070964467 | G11: =MAX('raw data'!R11:V11) -> 10.16 | H11: =MIN('raw data'!R11:V11) -> 9.9481 | I11: =IF(A11="bto",analyze!G11-B11,IF(A11="sto",B11-analyze!H11,0)) -> 0.31 | J11: =IF(B11>0,I11/B11,0) -> 0.031472081 | K11: ='raw data'!W11 -> 0.4377 | L11: ='raw data'!X11 -> 73.8073 | M11: ='raw data'!Y11 -> 67.0806 | N11: ='raw data'!Z11 -> 61.8745 | O11: ='raw data'!AA11 -> 59.7129 | P11: ='raw data'!AB11 -> 57.5748 | Q11: ='raw data'!AC11 -> -1.1135 | R11: ='raw data'!AD11 -> -1.2209 | ... BI11: ='raw data'!BU11 -> -136.6705 | CA11: =$L11-$P11 -> 16.2325 | CB11: =$Q11-$U11 -> 0.2542 | CC11: =$X11-$AB11 -> 0.3951
A12: ='raw data'!D12 -> Sell to Close | B12: ='raw data'!F12 -> 9.85 | C12: =MAX('raw data'!G12:P12) -> 38676.483 | D12: =MIN('raw data'!H12:Q12) -> -0.1 | E12: =IF($A12="bto",analyze!C12-'raw data'!F12,IF($A12="sto",'raw data'!F12-analyze!D12,0)) -> 0 | F12: =IF(B12>0,E12/B12,0) -> 0 | G12: =MAX('raw data'!R12:V12) -> 0 | H12: =MIN('raw data'!R12:V12) -> 0 | I12: =IF(A12="bto",analyze!G12-B12,IF(A12="sto",B12-analyze!H12,0)) -> 0 | J12: =IF(B12>0,I12/B12,0) -> 0 | K12: ='raw data'!W12 -> 0 | L12: ='raw data'!X12 -> 0 | M12: ='raw data'!Y12 -> 0 | N12: ='raw data'!Z12 -> 0 | O12: ='raw data'!AA12 -> 0 | P12: ='raw data'!AB12 -> 0 | Q12: ='raw data'!AC12 -> 0 | R12: ='raw data'!AD12 -> 0 | ... BI12: ='raw data'!BU12 -> 0 | CA12: =$L12-$P12 -> 0 | CB12: =$Q12-$U12 -> 0 | CC12: =$X12-$AB12 -> 0
A13: ='raw data'!D13 -> bto | B13: ='raw data'!F13 -> 9.885 | C13: =MAX('raw data'!G13:P13) -> 9.9345 | D13: =MIN('raw data'!H13:Q13) -> 9.875 | E13: =IF($A13="bto",analyze!C13-'raw data'!F13,IF($A13="sto",'raw data'!F13-analyze!D13,0)) -> 0.0495 | F13: =IF(B13>0,E13/B13,0) -> 0.0050075873 | G13: =MAX('raw data'!R13:V13) -> 10.1219 | H13: =MIN('raw data'!R13:V13) -> 9.9019 | I13: =IF(A13="bto",analyze!G13-B13,IF(A13="sto",B13-analyze!H13,0)) -> 0.2369 | J13: =IF(B13>0,I13/B13,0) -> 0.023965604 | K13: ='raw data'!W13 -> 0.3474 | L13: ='raw data'!X13 -> 72.3818 | M13: ='raw data'!Y13 -> 63.3361 | N13: ='raw data'!Z13 -> 61.4664 | O13: ='raw data'!AA13 -> 59.6367 | P13: ='raw data'!AB13 -> 78.1817 | Q13: ='raw data'!AC13 -> -0.9751 | R13: ='raw data'!AD13 -> -1.0476 | ... BI13: ='raw data'!BU13 -> -140.0745 | CA13: =$L13-$P13 -> -5.7999 | CB13: =$Q13-$U13 -> 0.0001 | CC13: =$X13-$AB13 -> 0.1094
A14: ='raw data'!D14 -> Sell to Close | B14: ='raw data'!F14 -> 9.94 | C14: =MAX('raw data'!G14:P14) -> 38676.489 | D14: =MIN('raw data'!H14:Q14) -> -0.05 | E14: =IF($A14="bto",analyze!C14-'raw data'!F14,IF($A14="sto",'raw data'!F14-analyze!D14,0)) -> 0 | F14: =IF(B14>0,E14/B14,0) -> 0 | G14: =MAX('raw data'!R14:V14) -> 0 | H14: =MIN('raw data'!R14:V14) -> 0 | I14: =IF(A14="bto",analyze!G14-B14,IF(A14="sto",B14-analyze!H14,0)) -> 0 | J14: =IF(B14>0,I14/B14,0) -> 0 | K14: ='raw data'!W14 -> 0 | L14: ='raw data'!X14 -> 0 | M14: ='raw data'!Y14 -> 0 | N14: ='raw data'!Z14 -> 0 | O14: ='raw data'!AA14 -> 0 | P14: ='raw data'!AB14 -> 0 | Q14: ='raw data'!AC14 -> 0 | R14: ='raw data'!AD14 -> 0 | ... BI14: ='raw data'!BU14 -> 0 | CA14: =$L14-$P14 -> 0 | CB14: =$Q14-$U14 -> 0 | CC14: =$X14-$AB14 -> 0
A15: ='raw data'!D15 -> bto | B15: ='raw data'!F15 -> 9.925 | C15: =MAX('raw data'!G15:P15) -> 9.99 | D15: =MIN('raw data'!H15:Q15) -> 9.925 | E15: =IF($A15="bto",analyze!C15-'raw data'!F15,IF($A15="sto",'raw data'!F15-analyze!D15,0)) -> 0.065 | F15: =IF(B15>0,E15/B15,0) -> 0.0065491184 | G15: =MAX('raw data'!R15:V15) -> 10.195 | H15: =MIN('raw data'!R15:V15) -> 9.91 | I15: =IF(A15="bto",analyze!G15-B15,IF(A15="sto",B15-analyze!H15,0)) -> 0.27 | J15: =IF(B15>0,I15/B15,0) -> 0.02720403 | K15: ='raw data'!W15 -> 0.2843 | L15: ='raw data'!X15 -> 65.0379 | M15: ='raw data'!Y15 -> 57.9349 | N15: ='raw data'!Z15 -> 69.2533 | O15: ='raw data'!AA15 -> 68.6824 | P15: ='raw data'!AB15 -> 64.9018 | Q15: ='raw data'!AC15 -> -0.7341 | R15: ='raw data'!AD15 -> -0.7973 | ... BI15: ='raw data'!BU15 -> -151.807 | CA15: =$L15-$P15 -> 0.1361 | CB15: =$Q15-$U15 -> 0.0729 | CC15: =$X15-$AB15 -> 0.2066
A16: ='raw data'!D16 -> Sell to Close | B16: ='raw data'!F16 -> 9.92 | C16: =MAX('raw data'!G16:P16) -> 38676.5 | D16: =MIN('raw data'!H16:Q16) -> -0.05 | E16: =IF($A16="bto",analyze!C16-'raw data'!F16,IF($A16="sto",'raw data'!F16-analyze!D16,0)) -> 0 | F16: =IF(B16>0,E16/B16,0) -> 0 | G16: =MAX('raw data'!R16:V16) -> 0 | H16: =MIN('raw data'!R16:V16) -> 0 | I16: =IF(A16="bto",analyze!G16-B16,IF(A16="sto",B16-analyze!H16,0)) -> 0 | J16: =IF(B16>0,I16/B16,0) -> 0 | K16: ='raw data'!W16 -> 0 | L16: ='raw data'!X16 -> 0 | M16: ='raw data'!Y16 -> 0 | N16: ='raw data'!Z16 -> 0 | O16: ='raw data'!AA16 -> 0 | P16: ='raw data'!AB16 -> 0 | Q16: ='raw data'!AC16 -> 0 | R16: ='raw data'!AD16 -> 0 | ... BI16: ='raw data'!BU16 -> 0 | CA16: =$L16-$P16 -> 0 | CB16: =$Q16-$U16 -> 0 | CC16: =$X16-$AB16 -> 0
A17: ='raw data'!D17 -> bto | B17: ='raw data'!F17 -> 10.01 | C17: =MAX('raw data'!G17:P17) -> 10.035 | D17: =MIN('raw data'!H17:Q17) -> 10.0031 | E17: =IF($A17="bto",analyze!C17-'raw data'!F17,IF($A17="sto",'raw data'!F17-analyze!D17,0)) -> 0.025 | F17: =IF(B17>0,E17/B17,0) -> 0.0024975025 | G17: =MAX('raw data'!R17:V17) -> 10.23 | H17: =MIN('raw data'!R17:V17) -> 9.885 | I17: =IF(A17="bto",analyze!G17-B17,IF(A17="sto",B17-analyze!H17,0)) -> 0.22 | J17: =IF(B17>0,I17/B17,0) -> 0.021978022 | K17: ='raw data'!W17 -> 0.7744 | L17: ='raw data'!X17 -> 72.1336 | M17: ='raw data'!Y17 -> 65.35 | N17: ='raw data'!Z17 -> 59.8168 | O17: ='raw data'!AA17 -> 54.2506 | P17: ='raw data'!AB17 -> 54.2506 | Q17: ='raw data'!AC17 -> -0.3664 | R17: ='raw data'!AD17 -> -0.4628 | ... BI17: ='raw data'!BU17 -> -154.4497 | CA17: =$L17-$P17 -> 17.883 | CB17: =$Q17-$U17 -> 0.1429 | CC17: =$X17-$AB17 -> 0.6519
A18: ='raw data'!D18 -> Sell to Close | B18: ='raw data'!F18 -> 10.17 | C18: =MAX('raw data'!G18:P18) -> 38676.519 | D18: =MIN('raw data'!H18:Q18) -> 0 | E18: =IF($A18="bto",analyze!C18-'raw data'!F18,IF($A18="sto",'raw data'!F18-analyze!D18,0)) -> 0 | F18: =IF(B18>0,E18/B18,0) -> 0 | G18: =MAX('raw data'!R18:V18) -> 0 | H18: =MIN('raw data'!R18:V18) -> 0 | I18: =IF(A18="bto",analyze!G18-B18,IF(A18="sto",B18-analyze!H18,0)) -> 0 | J18: =IF(B18>0,I18/B18,0) -> 0 | K18: ='raw data'!W18 -> 0 | L18: ='raw data'!X18 -> 0 | M18: ='raw data'!Y18 -> 0 | N18: ='raw data'!Z18 -> 0 | O18: ='raw data'!AA18 -> 0 | P18: ='raw data'!AB18 -> 0 | Q18: ='raw data'!AC18 -> 0 | R18: ='raw data'!AD18 -> 0 | ... BI18: ='raw data'!BU18 -> 0 | CA18: =$L18-$P18 -> 0 | CB18: =$Q18-$U18 -> 0 | CC18: =$X18-$AB18 -> 0
... A380: ='raw data'!D380 -> 0 | B380: ='raw data'!F380 -> 0 | C380: =MAX('raw data'!G380:P380) -> 0 | D380: =MIN('raw data'!H380:Q380) -> 0 | E380: =IF($A380="bto",analyze!C380-'raw data'!F380,IF($A380="sto",'raw data'!F380-analyze!D380,0)) -> 0 | F380: =IF(B380>0,E380/B380,0) -> 0 | G380: =MAX('raw data'!R380:V380) -> 0 | H380: =MIN('raw data'!R380:V380) -> 0 | I380: =IF(A380="bto",analyze!G380-B380,IF(A380="sto",B380-analyze!H380,0)) -> 0 | J380: =IF(B380>0,I380/B380,0) -> 0 | K380: ='raw data'!W380 -> 0 | L380: ='raw data'!X380 -> 0 | M380: ='raw data'!Y380 -> 0 | N380: ='raw data'!Z380 -> 0 | O380: ='raw data'!AA380 -> 0 | P380: ='raw data'!AB380 -> 0 | Q380: ='raw data'!AC380 -> 0 | R380: ='raw data'!AD380 -> 0 | ... BI380: ='raw data'!BU380 -> 0 | CA380: =$L380-$P380 -> 0 | CB380: =$Q380-$U380 -> 0 | CC380: =$X380-$AB380 -> 0
A381: ='raw data'!D381 -> 0 | B381: ='raw data'!F381 -> 0 | C381: =MAX('raw data'!G381:P381) -> 0 | D381: =MIN('raw data'!H381:Q381) -> 0 | E381: =IF($A381="bto",analyze!C381-'raw data'!F381,IF($A381="sto",'raw data'!F381-analyze!D381,0)) -> 0 | F381: =IF(B381>0,E381/B381,0) -> 0 | G381: =MAX('raw data'!R381:V381) -> 0 | H381: =MIN('raw data'!R381:V381) -> 0 | I381: =IF(A381="bto",analyze!G381-B381,IF(A381="sto",B381-analyze!H381,0)) -> 0 | J381: =IF(B381>0,I381/B381,0) -> 0 | K381: ='raw data'!W381 -> 0 | L381: ='raw data'!X381 -> 0 | M381: ='raw data'!Y381 -> 0 | N381: ='raw data'!Z381 -> 0 | O381: ='raw data'!AA381 -> 0 | P381: ='raw data'!AB381 -> 0 | Q381: ='raw data'!AC381 -> 0 | R381: ='raw data'!AD381 -> 0 | ... BI381: ='raw data'!BU381 -> 0
A382: ='raw data'!D382 -> 0 | B382: ='raw data'!F382 -> 0 | C382: =MAX('raw data'!G382:P382) -> 0 | D382: =MIN('raw data'!H382:Q382) -> 0 | E382: =IF($A382="bto",analyze!C382-'raw data'!F382,IF($A382="sto",'raw data'!F382-analyze!D382,0)) -> 0 | F382: =IF(B382>0,E382/B382,0) -> 0 | G382: =MAX('raw data'!R382:V382) -> 0 | H382: =MIN('raw data'!R382:V382) -> 0 | I382: =IF(A382="bto",analyze!G382-B382,IF(A382="sto",B382-analyze!H382,0)) -> 0 | J382: =IF(B382>0,I382/B382,0) -> 0 | K382: ='raw data'!W382 -> 0 | L382: ='raw data'!X382 -> 0 | M382: ='raw data'!Y382 -> 0 | N382: ='raw data'!Z382 -> 0 | O382: ='raw data'!AA382 -> 0 | P382: ='raw data'!AB382 -> 0 | Q382: ='raw data'!AC382 -> 0 | R382: ='raw data'!AD382 -> 0 | ... BI382: ='raw data'!BU382 -> 0
A383: ='raw data'!D383 -> 0 | B383: ='raw data'!F383 -> 0 | C383: =MAX('raw data'!G383:P383) -> 0 | D383: =MIN('raw data'!H383:Q383) -> 0 | E383: =IF($A383="bto",analyze!C383-'raw data'!F383,IF($A383="sto",'raw data'!F383-analyze!D383,0)) -> 0 | F383: =IF(B383>0,E383/B383,0) -> 0 | G383: =MAX('raw data'!R383:V383) -> 0 | H383: =MIN('raw data'!R383:V383) -> 0 | I383: =IF(A383="bto",analyze!G383-B383,IF(A383="sto",B383-analyze!H383,0)) -> 0 | J383: =IF(B383>0,I383/B383,0) -> 0 | K383: ='raw data'!W383 -> 0 | L383: ='raw data'!X383 -> 0 | M383: ='raw data'!Y383 -> 0 | N383: ='raw data'!Z383 -> 0 | O383: ='raw data'!AA383 -> 0 | P383: ='raw data'!AB383 -> 0 | Q383: ='raw data'!AC383 -> 0 | R383: ='raw data'!AD383 -> 0 | ... BI383: ='raw data'!BU383 -> 0
A384: ='raw data'!D384 -> 0 | B384: ='raw data'!F384 -> 0 | C384: =MAX('raw data'!G384:P384) -> 0 | D384: =MIN('raw data'!H384:Q384) -> 0 | E384: =IF($A384="bto",analyze!C384-'raw data'!F384,IF($A384="sto",'raw data'!F384-analyze!D384,0)) -> 0 | F384: =IF(B384>0,E384/B384,0) -> 0 | G384: =MAX('raw data'!R384:V384) -> 0 | H384: =MIN('raw data'!R384:V384) -> 0 | I384: =IF(A384="bto",analyze!G384-B384,IF(A384="sto",B384-analyze!H384,0)) -> 0 | J384: =IF(B384>0,I384/B384,0) -> 0 | K384: ='raw data'!W384 -> 0 | L384: ='raw data'!X384 -> 0 | M384: ='raw data'!Y384 -> 0 | N384: ='raw data'!Z384 -> 0 | O384: ='raw data'!AA384 -> 0 | P384: ='raw data'!AB384 -> 0 | Q384: ='raw data'!AC384 -> 0 | R384: ='raw data'!AD384 -> 0 | ... BI384: ='raw data'!BU384 -> 0
A385: ='raw data'!D385 -> 0 | B385: ='raw data'!F385 -> 0 | C385: =MAX('raw data'!G385:P385) -> 0 | D385: =MIN('raw data'!H385:Q385) -> 0 | E385: =IF($A385="bto",analyze!C385-'raw data'!F385,IF($A385="sto",'raw data'!F385-analyze!D385,0)) -> 0 | F385: =IF(B385>0,E385/B385,0) -> 0 | G385: =MAX('raw data'!R385:V385) -> 0 | H385: =MIN('raw data'!R385:V385) -> 0 | I385: =IF(A385="bto",analyze!G385-B385,IF(A385="sto",B385-analyze!H385,0)) -> 0 | J385: =IF(B385>0,I385/B385,0) -> 0 | K385: ='raw data'!W385 -> 0 | L385: ='raw data'!X385 -> 0 | M385: ='raw data'!Y385 -> 0 | N385: ='raw data'!Z385 -> 0 | O385: ='raw data'!AA385 -> 0 | P385: ='raw data'!AB385 -> 0 | Q385: ='raw data'!AC385 -> 0 | R385: ='raw data'!AD385 -> 0 | ... BI385: ='raw data'!BU385 -> 0
A386: ='raw data'!D386 -> 0 | B386: ='raw data'!F386 -> 0 | C386: =MAX('raw data'!G386:P386) -> 0 | D386: =MIN('raw data'!H386:Q386) -> 0 | E386: =IF($A386="bto",analyze!C386-'raw data'!F386,IF($A386="sto",'raw data'!F386-analyze!D386,0)) -> 0 | F386: =IF(B386>0,E386/B386,0) -> 0 | G386: =MAX('raw data'!R386:V386) -> 0 | H386: =MIN('raw data'!R386:V386) -> 0 | I386: =IF(A386="bto",analyze!G386-B386,IF(A386="sto",B386-analyze!H386,0)) -> 0 | J386: =IF(B386>0,I386/B386,0) -> 0 | K386: ='raw data'!W386 -> 0 | L386: ='raw data'!X386 -> 0 | M386: ='raw data'!Y386 -> 0 | N386: ='raw data'!Z386 -> 0 | O386: ='raw data'!AA386 -> 0 | P386: ='raw data'!AB386 -> 0 | Q386: ='raw data'!AC386 -> 0 | R386: ='raw data'!AD386 -> 0 | ... BI386: ='raw data'!BU386 -> 0
A387: ='raw data'!D387 -> 0 | B387: ='raw data'!F387 -> 0 | C387: =MAX('raw data'!G387:P387) -> 0 | D387: =MIN('raw data'!H387:Q387) -> 0 | E387: =IF($A387="bto",analyze!C387-'raw data'!F387,IF($A387="sto",'raw data'!F387-analyze!D387,0)) -> 0 | F387: =IF(B387>0,E387/B387,0) -> 0 | G387: =MAX('raw data'!R387:V387) -> 0 | H387: =MIN('raw data'!R387:V387) -> 0 | I387: =IF(A387="bto",analyze!G387-B387,IF(A387="sto",B387-analyze!H387,0)) -> 0 | J387: =IF(B387>0,I387/B387,0) -> 0 | K387: ='raw data'!W387 -> 0 | L387: ='raw data'!X387 -> 0 | M387: ='raw data'!Y387 -> 0 | N387: ='raw data'!Z387 -> 0 | O387: ='raw data'!AA387 -> 0 | P387: ='raw data'!AB387 -> 0 | Q387: ='raw data'!AC387 -> 0 | R387: ='raw data'!AD387 -> 0 | ... BI387: ='raw data'!BU387 -> 0
A388: ='raw data'!D388 -> 0 | B388: ='raw data'!F388 -> 0 | C388: =MAX('raw data'!G388:P388) -> 0 | D388: =MIN('raw data'!H388:Q388) -> 0 | E388: =IF($A388="bto",analyze!C388-'raw data'!F388,IF($A388="sto",'raw data'!F388-analyze!D388,0)) -> 0 | F388: =IF(B388>0,E388/B388,0) -> 0 | G388: =MAX('raw data'!R388:V388) -> 0 | H388: =MIN('raw data'!R388:V388) -> 0 | I388: =IF(A388="bto",analyze!G388-B388,IF(A388="sto",B388-analyze!H388,0)) -> 0 | J388: =IF(B388>0,I388/B388,0) -> 0 | K388: ='raw data'!W388 -> 0 | L388: ='raw data'!X388 -> 0 | M388: ='raw data'!Y388 -> 0 | N388: ='raw data'!Z388 -> 0 | O388: ='raw data'!AA388 -> 0 | P388: ='raw data'!AB388 -> 0 | Q388: ='raw data'!AC388 -> 0 | R388: ='raw data'!AD388 -> 0 | ... BI388: ='raw data'!BU388 -> 0
A389: ='raw data'!D389 -> 0 | B389: ='raw data'!F389 -> 0 | C389: =MAX('raw data'!G389:P389) -> 0 | D389: =MIN('raw data'!H389:Q389) -> 0 | E389: =IF($A389="bto",analyze!C389-'raw data'!F389,IF($A389="sto",'raw data'!F389-analyze!D389,0)) -> 0 | F389: =IF(B389>0,E389/B389,0) -> 0 | G389: =MAX('raw data'!R389:V389) -> 0 | H389: =MIN('raw data'!R389:V389) -> 0 | I389: =IF(A389="bto",analyze!G389-B389,IF(A389="sto",B389-analyze!H389,0)) -> 0 | J389: =IF(B389>0,I389/B389,0) -> 0 | K389: ='raw data'!W389 -> 0 | L389: ='raw data'!X389 -> 0 | M389: ='raw data'!Y389 -> 0 | N389: ='raw data'!Z389 -> 0 | O389: ='raw data'!AA389 -> 0 | P389: ='raw data'!AB389 -> 0 | Q389: ='raw data'!AC389 -> 0 | R389: ='raw data'!AD389 -> 0 | ... BI389: ='raw data'!BU389 -> 0
A390: ='raw data'!D390 -> 0 | B390: ='raw data'!F390 -> 0 | C390: =MAX('raw data'!G390:P390) -> 0 | D390: =MIN('raw data'!H390:Q390) -> 0 | E390: =IF($A390="bto",analyze!C390-'raw data'!F390,IF($A390="sto",'raw data'!F390-analyze!D390,0)) -> 0 | F390: =IF(B390>0,E390/B390,0) -> 0 | G390: =MAX('raw data'!R390:V390) -> 0 | H390: =MIN('raw data'!R390:V390) -> 0 | I390: =IF(A390="bto",analyze!G390-B390,IF(A390="sto",B390-analyze!H390,0)) -> 0 | J390: =IF(B390>0,I390/B390,0) -> 0 | K390: ='raw data'!W390 -> 0 | L390: ='raw data'!X390 -> 0 | M390: ='raw data'!Y390 -> 0 | N390: ='raw data'!Z390 -> 0 | O390: ='raw data'!AA390 -> 0 | P390: ='raw data'!AB390 -> 0 | Q390: ='raw data'!AC390 -> 0 | R390: ='raw data'!AD390 -> 0 | ... BI390: ='raw data'!BU390 -> 0
A391: ='raw data'!D391 -> 0 | B391: ='raw data'!F391 -> 0 | C391: =MAX('raw data'!G391:P391) -> 0 | D391: =MIN('raw data'!H391:Q391) -> 0 | E391: =IF($A391="bto",analyze!C391-'raw data'!F391,IF($A391="sto",'raw data'!F391-analyze!D391,0)) -> 0 | F391: =IF(B391>0,E391/B391,0) -> 0 | G391: =MAX('raw data'!R391:V391) -> 0 | H391: =MIN('raw data'!R391:V391) -> 0 | I391: =IF(A391="bto",analyze!G391-B391,IF(A391="sto",B391-analyze!H391,0)) -> 0 | J391: =IF(B391>0,I391/B391,0) -> 0 | K391: ='raw data'!W391 -> 0 | L391: ='raw data'!X391 -> 0 | M391: ='raw data'!Y391 -> 0 | N391: ='raw data'!Z391 -> 0 | O391: ='raw data'!AA391 -> 0 | P391: ='raw data'!AB391 -> 0 | Q391: ='raw data'!AC391 -> 0 | R391: ='raw data'!AD391 -> 0 | ... BI391: ='raw data'!BU391 -> 0
A392: ='raw data'!D392 -> 0 | B392: ='raw data'!F392 -> 0 | C392: =MAX('raw data'!G392:P392) -> 0 | D392: =MIN('raw data'!H392:Q392) -> 0 | E392: =IF($A392="bto",analyze!C392-'raw data'!F392,IF($A392="sto",'raw data'!F392-analyze!D392,0)) -> 0 | F392: =IF(B392>0,E392/B392,0) -> 0 | G392: =MAX('raw data'!R392:V392) -> 0 | H392: =MIN('raw data'!R392:V392) -> 0 | I392: =IF(A392="bto",analyze!G392-B392,IF(A392="sto",B392-analyze!H392,0)) -> 0 | J392: =IF(B392>0,I392/B392,0) -> 0 | K392: ='raw data'!W392 -> 0 | L392: ='raw data'!X392 -> 0 | M392: ='raw data'!Y392 -> 0 | N392: ='raw data'!Z392 -> 0 | O392: ='raw data'!AA392 -> 0 | P392: ='raw data'!AB392 -> 0 | Q392: ='raw data'!AC392 -> 0 | R392: ='raw data'!AD392 -> 0 | ... BI392: ='raw data'!BU392 -> 0
... A406: ='raw data'!D406 -> 0 | B406: ='raw data'!F406 -> 0 | C406: =MAX('raw data'!G406:P406) -> 0 | D406: =MIN('raw data'!H406:Q406) -> 0 | E406: =IF($A406="bto",analyze!C406-'raw data'!F406,IF($A406="sto",'raw data'!F406-analyze!D406,0)) -> 0 | F406: =IF(B406>0,E406/B406,0) -> 0 | G406: =MAX('raw data'!R406:V406) -> 0 | H406: =MIN('raw data'!R406:V406) -> 0 | I406: =IF(A406="bto",analyze!G406-B406,IF(A406="sto",B406-analyze!H406,0)) -> 0 | J406: =IF(B406>0,I406/B406,0) -> 0 | K406: ='raw data'!W406 -> 0 | L406: ='raw data'!X406 -> 0 | M406: ='raw data'!Y406 -> 0 | N406: ='raw data'!Z406 -> 0 | O406: ='raw data'!AA406 -> 0 | P406: ='raw data'!AB406 -> 0 | Q406: ='raw data'!AC406 -> 0 | R406: ='raw data'!AD406 -> 0 | ... BI406: ='raw data'!BU406 -> 0

Sheet cs bto
A1: sto/bto | B1: price | C1: short-term max | D1: short-term min | E1: short-term success | F1: STS % | G1: long-term max | H1: short-term min | I1: long-term success | J1: LTS % | K1: =titled!W3 -> goodvolume | L1: =titled!X3 -> rsi | M1: =titled!Y3 -> rsi-1 | N1: =titled!Z3 -> rsi-2 | O1: =titled!AA3 -> rsi-3 | P1: =titled!AB3 -> rsi-4 | Q1: =titled!AC3 -> dvi | R1: =titled!AD3 -> dvi-1 | ... BI1: =titled!BU3 -> vold[50]/M | CA1: drsi | CB1: ddvi | CC1: drs | CD1: dvold | CE1: dspy
A7: ='raw data'!D7 -> bto | B7: ='raw data'!F7 -> 9.82 | C7: =MAX('raw data'!G7:P7) -> 9.8 | D7: =MIN('raw data'!H7:Q7) -> 9.725 | E7: =IF($A7="bto",analyze!C7-'raw data'!F7,IF($A7="sto",'raw data'!F7-analyze!D7,0)) -> -0.02 | F7: =IF(B7>0,E7/B7,0) -> -0.0020366599 | G7: =MAX('raw data'!R7:V7) -> 10.085 | H7: =MIN('raw data'!R7:V7) -> 9.7381 | I7: =IF(A7="bto",analyze!G7-B7,IF(A7="sto",B7-analyze!H7,0)) -> 0.265 | J7: =IF(B7>0,I7/B7,0) -> 0.026985743 | K7: ='raw data'!W7 -> 0.1535 | L7: ='raw data'!X7 -> 48.2988 | M7: ='raw data'!Y7 -> 40.023 | N7: ='raw data'!Z7 -> 43.5067 | O7: ='raw data'!AA7 -> 43.5067 | P7: ='raw data'!AB7 -> 39.5063 | Q7: ='raw data'!AC7 -> -1.155 | R7: ='raw data'!AD7 -> -1.2343 | ... BI7: ='raw data'!BU7 -> 368.5387 | CA7: =$L7-$P7 -> 8.7925 | CB7: =$Q7-$U7 -> -0.0478 | CC7: =$X7-$AB7 -> 0.4543 | CD7: =BF7-BH7 -> -19.3454 | CE7: =AZ7-BA7 -> 0.11
A8: ='raw data'!D8 -> Sell to Close | B8: ='raw data'!F8 -> 9.73 | C8: =MAX('raw data'!G8:P8) -> 38676.417 | D8: =MIN('raw data'!H8:Q8) -> -0.1 | E8: =IF($A8="bto",analyze!C8-'raw data'!F8,IF($A8="sto",'raw data'!F8-analyze!D8,0)) -> 0 | F8: =IF(B8>0,E8/B8,0) -> 0 | G8: =MAX('raw data'!R8:V8) -> 0 | H8: =MIN('raw data'!R8:V8) -> 0 | I8: =IF(A8="bto",analyze!G8-B8,IF(A8="sto",B8-analyze!H8,0)) -> 0 | J8: =IF(B8>0,I8/B8,0) -> 0 | K8: ='raw data'!W8 -> 0 | L8: ='raw data'!X8 -> 0 | M8: ='raw data'!Y8 -> 0 | N8: ='raw data'!Z8 -> 0 | O8: ='raw data'!AA8 -> 0 | P8: ='raw data'!AB8 -> 0 | Q8: ='raw data'!AC8 -> 0 | R8: ='raw data'!AD8 -> 0 | ... BI8: ='raw data'!BU8 -> 0 | CA8: =$L8-$P8 -> 0 | CB8: =$Q8-$U8 -> 0 | CC8: =$X8-$AB8 -> 0
A9: ='raw data'!D9 -> bto | B9: ='raw data'!F9 -> 9.821 | C9: =MAX('raw data'!G9:P9) -> 9.835 | D9: =MIN('raw data'!H9:Q9) -> 9.81 | E9: =IF($A9="bto",analyze!C9-'raw data'!F9,IF($A9="sto",'raw data'!F9-analyze!D9,0)) -> 0.014 | F9: =IF(B9>0,E9/B9,0) -> 0.0014255167 | G9: =MAX('raw data'!R9:V9) -> 10.1419 | H9: =MIN('raw data'!R9:V9) -> 9.771 | I9: =IF(A9="bto",analyze!G9-B9,IF(A9="sto",B9-analyze!H9,0)) -> 0.3209 | J9: =IF(B9>0,I9/B9,0) -> 0.03267488 | K9: ='raw data'!W9 -> 0.4361 | L9: ='raw data'!X9 -> 73.8257 | M9: ='raw data'!Y9 -> 67.8365 | N9: ='raw data'!Z9 -> 66.4443 | O9: ='raw data'!AA9 -> 61.171 | P9: ='raw data'!AB9 -> 58.9742 | Q9: ='raw data'!AC9 -> -1.2664 | R9: ='raw data'!AD9 -> -1.368 | ... BI9: ='raw data'!BU9 -> -116.3051 | CA9: =$L9-$P9 -> 14.8515 | CB9: =$Q9-$U9 -> 0.1996 | CC9: =$X9-$AB9 -> 0.5107 | CD9: =BF9-BH9 -> -1.2523 | CE9: =AZ9-BA9 -> 0.25
A10: ='raw data'!D10 -> Sell to Close | B10: ='raw data'!F10 -> 9.82 | C10: =MAX('raw data'!G10:P10) -> 38676.465 | D10: =MIN('raw data'!H10:Q10) -> -0.1 | E10: =IF($A10="bto",analyze!C10-'raw data'!F10,IF($A10="sto",'raw data'!F10-analyze!D10,0)) -> 0 | F10: =IF(B10>0,E10/B10,0) -> 0 | G10: =MAX('raw data'!R10:V10) -> 0 | H10: =MIN('raw data'!R10:V10) -> 0 | I10: =IF(A10="bto",analyze!G10-B10,IF(A10="sto",B10-analyze!H10,0)) -> 0 | J10: =IF(B10>0,I10/B10,0) -> 0 | K10: ='raw data'!W10 -> 0 | L10: ='raw data'!X10 -> 0 | M10: ='raw data'!Y10 -> 0 | N10: ='raw data'!Z10 -> 0 | O10: ='raw data'!AA10 -> 0 | P10: ='raw data'!AB10 -> 0 | Q10: ='raw data'!AC10 -> 0 | R10: ='raw data'!AD10 -> 0 | ... BI10: ='raw data'!BU10 -> 0 | CA10: =$L10-$P10 -> 0 | CB10: =$Q10-$U10 -> 0 | CC10: =$X10-$AB10 -> 0
A11: ='raw data'!D11 -> bto | B11: ='raw data'!F11 -> 9.85 | C11: =MAX('raw data'!G11:P11) -> 9.9199 | D11: =MIN('raw data'!H11:Q11) -> 9.85 | E11: =IF($A11="bto",analyze!C11-'raw data'!F11,IF($A11="sto",'raw data'!F11-analyze!D11,0)) -> 0.0699 | F11: =IF(B11>0,E11/B11,0) -> 0.0070964467 | G11: =MAX('raw data'!R11:V11) -> 10.16 | H11: =MIN('raw data'!R11:V11) -> 9.9481 | I11: =IF(A11="bto",analyze!G11-B11,IF(A11="sto",B11-analyze!H11,0)) -> 0.31 | J11: =IF(B11>0,I11/B11,0) -> 0.031472081 | K11: ='raw data'!W11 -> 0.4377 | L11: ='raw data'!X11 -> 73.8073 | M11: ='raw data'!Y11 -> 67.0806 | N11: ='raw data'!Z11 -> 61.8745 | O11: ='raw data'!AA11 -> 59.7129 | P11: ='raw data'!AB11 -> 57.5748 | Q11: ='raw data'!AC11 -> -1.1135 | R11: ='raw data'!AD11 -> -1.2209 | ... BI11: ='raw data'!BU11 -> -136.6705 | CA11: =$L11-$P11 -> 16.2325 | CB11: =$Q11-$U11 -> 0.2542 | CC11: =$X11-$AB11 -> 0.3951 | CD11: =BF11-BH11 -> 0.1062 | CE11: =AZ11-BA11 -> 0.35
A12: ='raw data'!D12 -> Sell to Close | B12: ='raw data'!F12 -> 9.85 | C12: =MAX('raw data'!G12:P12) -> 38676.483 | D12: =MIN('raw data'!H12:Q12) -> -0.1 | E12: =IF($A12="bto",analyze!C12-'raw data'!F12,IF($A12="sto",'raw data'!F12-analyze!D12,0)) -> 0 | F12: =IF(B12>0,E12/B12,0) -> 0 | G12: =MAX('raw data'!R12:V12) -> 0 | H12: =MIN('raw data'!R12:V12) -> 0 | I12: =IF(A12="bto",analyze!G12-B12,IF(A12="sto",B12-analyze!H12,0)) -> 0 | J12: =IF(B12>0,I12/B12,0) -> 0 | K12: ='raw data'!W12 -> 0 | L12: ='raw data'!X12 -> 0 | M12: ='raw data'!Y12 -> 0 | N12: ='raw data'!Z12 -> 0 | O12: ='raw data'!AA12 -> 0 | P12: ='raw data'!AB12 -> 0 | Q12: ='raw data'!AC12 -> 0 | R12: ='raw data'!AD12 -> 0 | ... BI12: ='raw data'!BU12 -> 0 | CA12: =$L12-$P12 -> 0 | CB12: =$Q12-$U12 -> 0 | CC12: =$X12-$AB12 -> 0
A13: ='raw data'!D13 -> bto | B13: ='raw data'!F13 -> 9.885 | C13: =MAX('raw data'!G13:P13) -> 9.9345 | D13: =MIN('raw data'!H13:Q13) -> 9.875 | E13: =IF($A13="bto",analyze!C13-'raw data'!F13,IF($A13="sto",'raw data'!F13-analyze!D13,0)) -> 0.0495 | F13: =IF(B13>0,E13/B13,0) -> 0.0050075873 | G13: =MAX('raw data'!R13:V13) -> 10.1219 | H13: =MIN('raw data'!R13:V13) -> 9.9019 | I13: =IF(A13="bto",analyze!G13-B13,IF(A13="sto",B13-analyze!H13,0)) -> 0.2369 | J13: =IF(B13>0,I13/B13,0) -> 0.023965604 | K13: ='raw data'!W13 -> 0.3474 | L13: ='raw data'!X13 -> 72.3818 | M13: ='raw data'!Y13 -> 63.3361 | N13: ='raw data'!Z13 -> 61.4664 | O13: ='raw data'!AA13 -> 59.6367 | P13: ='raw data'!AB13 -> 78.1817 | Q13: ='raw data'!AC13 -> -0.9751 | R13: ='raw data'!AD13 -> -1.0476 | ... BI13: ='raw data'!BU13 -> -140.0745 | CA13: =$L13-$P13 -> -5.7999 | CB13: =$Q13-$U13 -> 0.0001 | CC13: =$X13-$AB13 -> 0.1094 | CD13: =BF13-BH13 -> 1.0583 | CE13: =AZ13-BA13 -> 0.08
A14: ='raw data'!D14 -> Sell to Close | B14: ='raw data'!F14 -> 9.94 | C14: =MAX('raw data'!G14:P14) -> 38676.489 | D14: =MIN('raw data'!H14:Q14) -> -0.05 | E14: =IF($A14="bto",analyze!C14-'raw data'!F14,IF($A14="sto",'raw data'!F14-analyze!D14,0)) -> 0 | F14: =IF(B14>0,E14/B14,0) -> 0 | G14: =MAX('raw data'!R14:V14) -> 0 | H14: =MIN('raw data'!R14:V14) -> 0 | I14: =IF(A14="bto",analyze!G14-B14,IF(A14="sto",B14-analyze!H14,0)) -> 0 | J14: =IF(B14>0,I14/B14,0) -> 0 | K14: ='raw data'!W14 -> 0 | L14: ='raw data'!X14 -> 0 | M14: ='raw data'!Y14 -> 0 | N14: ='raw data'!Z14 -> 0 | O14: ='raw data'!AA14 -> 0 | P14: ='raw data'!AB14 -> 0 | Q14: ='raw data'!AC14 -> 0 | R14: ='raw data'!AD14 -> 0 | ... BI14: ='raw data'!BU14 -> 0 | CA14: =$L14-$P14 -> 0 | CB14: =$Q14-$U14 -> 0 | CC14: =$X14-$AB14 -> 0
A15: ='raw data'!D15 -> bto | B15: ='raw data'!F15 -> 9.925 | C15: =MAX('raw data'!G15:P15) -> 9.99 | D15: =MIN('raw data'!H15:Q15) -> 9.925 | E15: =IF($A15="bto",analyze!C15-'raw data'!F15,IF($A15="sto",'raw data'!F15-analyze!D15,0)) -> 0.065 | F15: =IF(B15>0,E15/B15,0) -> 0.0065491184 | G15: =MAX('raw data'!R15:V15) -> 10.195 | H15: =MIN('raw data'!R15:V15) -> 9.91 | I15: =IF(A15="bto",analyze!G15-B15,IF(A15="sto",B15-analyze!H15,0)) -> 0.27 | J15: =IF(B15>0,I15/B15,0) -> 0.02720403 | K15: ='raw data'!W15 -> 0.2843 | L15: ='raw data'!X15 -> 65.0379 | M15: ='raw data'!Y15 -> 57.9349 | N15: ='raw data'!Z15 -> 69.2533 | O15: ='raw data'!AA15 -> 68.6824 | P15: ='raw data'!AB15 -> 64.9018 | Q15: ='raw data'!AC15 -> -0.7341 | R15: ='raw data'!AD15 -> -0.7973 | ... BI15: ='raw data'!BU15 -> -151.807 | CA15: =$L15-$P15 -> 0.1361 | CB15: =$Q15-$U15 -> 0.0729 | CC15: =$X15-$AB15 -> 0.2066 | CD15: =BF15-BH15 -> -0.6746 | CE15: =AZ15-BA15 -> -0.01
A16: ='raw data'!D16 -> Sell to Close | B16: ='raw data'!F16 -> 9.92 | C16: =MAX('raw data'!G16:P16) -> 38676.5 | D16: =MIN('raw data'!H16:Q16) -> -0.05 | E16: =IF($A16="bto",analyze!C16-'raw data'!F16,IF($A16="sto",'raw data'!F16-analyze!D16,0)) -> 0 | F16: =IF(B16>0,E16/B16,0) -> 0 | G16: =MAX('raw data'!R16:V16) -> 0 | H16: =MIN('raw data'!R16:V16) -> 0 | I16: =IF(A16="bto",analyze!G16-B16,IF(A16="sto",B16-analyze!H16,0)) -> 0 | J16: =IF(B16>0,I16/B16,0) -> 0 | K16: ='raw data'!W16 -> 0 | L16: ='raw data'!X16 -> 0 | M16: ='raw data'!Y16 -> 0 | N16: ='raw data'!Z16 -> 0 | O16: ='raw data'!AA16 -> 0 | P16: ='raw data'!AB16 -> 0 | Q16: ='raw data'!AC16 -> 0 | R16: ='raw data'!AD16 -> 0 | ... BI16: ='raw data'!BU16 -> 0 | CA16: =$L16-$P16 -> 0 | CB16: =$Q16-$U16 -> 0 | CC16: =$X16-$AB16 -> 0
A17: ='raw data'!D17 -> bto | B17: ='raw data'!F17 -> 10.01 | C17: =MAX('raw data'!G17:P17) -> 10.035 | D17: =MIN('raw data'!H17:Q17) -> 10.0031 | E17: =IF($A17="bto",analyze!C17-'raw data'!F17,IF($A17="sto",'raw data'!F17-analyze!D17,0)) -> 0.025 | F17: =IF(B17>0,E17/B17,0) -> 0.0024975025 | G17: =MAX('raw data'!R17:V17) -> 10.23 | H17: =MIN('raw data'!R17:V17) -> 9.885 | I17: =IF(A17="bto",analyze!G17-B17,IF(A17="sto",B17-analyze!H17,0)) -> 0.22 | J17: =IF(B17>0,I17/B17,0) -> 0.021978022 | K17: ='raw data'!W17 -> 0.7744 | L17: ='raw data'!X17 -> 72.1336 | M17: ='raw data'!Y17 -> 65.35 | N17: ='raw data'!Z17 -> 59.8168 | O17: ='raw data'!AA17 -> 54.2506 | P17: ='raw data'!AB17 -> 54.2506 | Q17: ='raw data'!AC17 -> -0.3664 | R17: ='raw data'!AD17 -> -0.4628 | ... BI17: ='raw data'!BU17 -> -154.4497 | CA17: =$L17-$P17 -> 17.883 | CB17: =$Q17-$U17 -> 0.1429 | CC17: =$X17-$AB17 -> 0.6519 | CD17: =BF17-BH17 -> 1.951 | CE17: =AZ17-BA17 -> -0.0571
A18: ='raw data'!D18 -> Sell to Close | B18: ='raw data'!F18 -> 10.17 | C18: =MAX('raw data'!G18:P18) -> 38676.519 | D18: =MIN('raw data'!H18:Q18) -> 0 | E18: =IF($A18="bto",analyze!C18-'raw data'!F18,IF($A18="sto",'raw data'!F18-analyze!D18,0)) -> 0 | F18: =IF(B18>0,E18/B18,0) -> 0 | G18: =MAX('raw data'!R18:V18) -> 0 | H18: =MIN('raw data'!R18:V18) -> 0 | I18: =IF(A18="bto",analyze!G18-B18,IF(A18="sto",B18-analyze!H18,0)) -> 0 | J18: =IF(B18>0,I18/B18,0) -> 0 | K18: ='raw data'!W18 -> 0 | L18: ='raw data'!X18 -> 0 | M18: ='raw data'!Y18 -> 0 | N18: ='raw data'!Z18 -> 0 | O18: ='raw data'!AA18 -> 0 | P18: ='raw data'!AB18 -> 0 | Q18: ='raw data'!AC18 -> 0 | R18: ='raw data'!AD18 -> 0 | ... BI18: ='raw data'!BU18 -> 0 | CA18: =$L18-$P18 -> 0 | CB18: =$Q18-$U18 -> 0 | CC18: =$X18-$AB18 -> 0
A19: ='raw data'!D19 -> sto | B19: ='raw data'!F19 -> 9.99 | C19: =MAX('raw data'!G19:P19) -> 10.0349 | D19: =MIN('raw data'!H19:Q19) -> 9.98 | E19: =IF($A19="bto",analyze!C19-'raw data'!F19,IF($A19="sto",'raw data'!F19-analyze!D19,0)) -> 0.01 | F19: =IF(B19>0,E19/B19,0) -> 0.001001001 | G19: =MAX('raw data'!R19:V19) -> 10.055 | H19: =MIN('raw data'!R19:V19) -> 9.73 | I19: =IF(A19="bto",analyze!G19-B19,IF(A19="sto",B19-analyze!H19,0)) -> 0.26 | J19: =IF(B19>0,I19/B19,0) -> 0.026026026 | K19: ='raw data'!W19 -> 0.2724 | L19: ='raw data'!X19 -> 33.8683 | M19: ='raw data'!Y19 -> 43.2268 | N19: ='raw data'!Z19 -> 47.0156 | O19: ='raw data'!AA19 -> 54.8995 | P19: ='raw data'!AB19 -> 31.8095 | Q19: ='raw data'!AC19 -> 0.1774 | R19: ='raw data'!AD19 -> 0.2188 | ... BI19: ='raw data'!BU19 -> -135.3065 | CA19: =$L19-$P19 -> 2.0588 | CB19: =$Q19-$U19 -> -0.2212 | CC19: =$X19-$AB19 -> -0.3678
A20: ='raw data'!D20 -> Buy to Close | B20: ='raw data'!F20 -> 10.01 | C20: =MAX('raw data'!G20:P20) -> 38676.572 | D20: =MIN('raw data'!H20:Q20) -> -0.02 | E20: =IF($A20="bto",analyze!C20-'raw data'!F20,IF($A20="sto",'raw data'!F20-analyze!D20,0)) -> 0 | F20: =IF(B20>0,E20/B20,0) -> 0 | G20: =MAX('raw data'!R20:V20) -> 0 | H20: =MIN('raw data'!R20:V20) -> 0 | I20: =IF(A20="bto",analyze!G20-B20,IF(A20="sto",B20-analyze!H20,0)) -> 0 | J20: =IF(B20>0,I20/B20,0) -> 0 | K20: ='raw data'!W20 -> 0 | L20: ='raw data'!X20 -> 0 | M20: ='raw data'!Y20 -> 0 | N20: ='raw data'!Z20 -> 0 | O20: ='raw data'!AA20 -> 0 | P20: ='raw data'!AB20 -> 0 | Q20: ='raw data'!AC20 -> 0 | R20: ='raw data'!AD20 -> 0 | ... BI20: ='raw data'!BU20 -> 0 | CA20: =$L20-$P20 -> 0 | CB20: =$Q20-$U20 -> 0 | CC20: =$X20-$AB20 -> 0
A21: ='raw data'!D21 -> bto | B21: ='raw data'!F21 -> 9.935 | C21: =MAX('raw data'!G21:P21) -> 9.9683 | D21: =MIN('raw data'!H21:Q21) -> 9.9 | E21: =IF($A21="bto",analyze!C21-'raw data'!F21,IF($A21="sto",'raw data'!F21-analyze!D21,0)) -> 0.0333 | F21: =IF(B21>0,E21/B21,0) -> 0.0033517866 | G21: =MAX('raw data'!R21:V21) -> 9.993 | H21: =MIN('raw data'!R21:V21) -> 9.7 | I21: =IF(A21="bto",analyze!G21-B21,IF(A21="sto",B21-analyze!H21,0)) -> 0.058 | J21: =IF(B21>0,I21/B21,0) -> 0.0058379467 | K21: ='raw data'!W21 -> 0.7234 | L21: ='raw data'!X21 -> 68.8069 | M21: ='raw data'!Y21 -> 54.4319 | N21: ='raw data'!Z21 -> 56.4222 | O21: ='raw data'!AA21 -> 46.2158 | P21: ='raw data'!AB21 -> 49.0358 | Q21: ='raw data'!AC21 -> 0.3142 | R21: ='raw data'!AD21 -> 0.2558 | ... BI21: ='raw data'!BU21 -> -212.5653 | CA21: =$L21-$P21 -> 19.7711 | CB21: =$Q21-$U21 -> 0.0905 | CC21: =$X21-$AB21 -> 0.4557 | CD21: =BF21-BH21 -> -20.1108 | CE21: =AZ21-BA21 -> 0
A22: ='raw data'!D22 -> Sell to Close | B22: ='raw data'!F22 -> 9.98 | C22: =MAX('raw data'!G22:P22) -> 38676.656 | D22: =MIN('raw data'!H22:Q22) -> 0 | E22: =IF($A22="bto",analyze!C22-'raw data'!F22,IF($A22="sto",'raw data'!F22-analyze!D22,0)) -> 0 | F22: =IF(B22>0,E22/B22,0) -> 0 | G22: =MAX('raw data'!R22:V22) -> 0 | H22: =MIN('raw data'!R22:V22) -> 0 | I22: =IF(A22="bto",analyze!G22-B22,IF(A22="sto",B22-analyze!H22,0)) -> 0 | J22: =IF(B22>0,I22/B22,0) -> 0 | K22: ='raw data'!W22 -> 0 | L22: ='raw data'!X22 -> 0 | M22: ='raw data'!Y22 -> 0 | N22: ='raw data'!Z22 -> 0 | O22: ='raw data'!AA22 -> 0 | P22: ='raw data'!AB22 -> 0 | Q22: ='raw data'!AC22 -> 0 | R22: ='raw data'!AD22 -> 0 | ... BI22: ='raw data'!BU22 -> 0 | CA22: =$L22-$P22 -> 0 | CB22: =$Q22-$U22 -> 0 | CC22: =$X22-$AB22 -> 0
A23: ='raw data'!D23 -> bto | B23: ='raw data'!F23 -> 10.03 | C23: =MAX('raw data'!G23:P23) -> 10.09 | D23: =MIN('raw data'!H23:Q23) -> 10.0135 | E23: =IF($A23="bto",analyze!C23-'raw data'!F23,IF($A23="sto",'raw data'!F23-analyze!D23,0)) -> 0.06 | F23: =IF(B23>0,E23/B23,0) -> 0.0059820538 | G23: =MAX('raw data'!R23:V23) -> 10.055 | H23: =MIN('raw data'!R23:V23) -> 9.6281 | I23: =IF(A23="bto",analyze!G23-B23,IF(A23="sto",B23-analyze!H23,0)) -> 0.025 | J23: =IF(B23>0,I23/B23,0) -> 0.0024925224 | K23: ='raw data'!W23 -> 0.3374 | L23: ='raw data'!X23 -> 85.2022 | M23: ='raw data'!Y23 -> 76.4152 | N23: ='raw data'!Z23 -> 70.1031 | O23: ='raw data'!AA23 -> 70.1031 | P23: ='raw data'!AB23 -> 66.5684 | Q23: ='raw data'!AC23 -> 0.8058 | R23: ='raw data'!AD23 -> 0.6961 | ... BI23: ='raw data'!BU23 -> -223.5456 | CA23: =$L23-$P23 -> 18.6338 | CB23: =$Q23-$U23 -> 0.3787 | CC23: =$X23-$AB23 -> 0.4606 | CD23: =BF23-BH23 -> -28.9841 | CE23: =AZ23-BA23 -> 0.09
A24: ='raw data'!D24 -> Sell to Close | B24: ='raw data'!F24 -> 10.06 | C24: =MAX('raw data'!G24:P24) -> 38706.397 | D24: =MIN('raw data'!H24:Q24) -> 0 | E24: =IF($A24="bto",analyze!C24-'raw data'!F24,IF($A24="sto",'raw data'!F24-analyze!D24,0)) -> 0 | F24: =IF(B24>0,E24/B24,0) -> 0 | G24: =MAX('raw data'!R24:V24) -> 0 | H24: =MIN('raw data'!R24:V24) -> 0 | I24: =IF(A24="bto",analyze!G24-B24,IF(A24="sto",B24-analyze!H24,0)) -> 0 | J24: =IF(B24>0,I24/B24,0) -> 0 | K24: ='raw data'!W24 -> 0 | L24: ='raw data'!X24 -> 0 | M24: ='raw data'!Y24 -> 0 | N24: ='raw data'!Z24 -> 0 | O24: ='raw data'!AA24 -> 0 | P24: ='raw data'!AB24 -> 0 | Q24: ='raw data'!AC24 -> 0 | R24: ='raw data'!AD24 -> 0 | ... BI24: ='raw data'!BU24 -> 0 | CA24: =$L24-$P24 -> 0 | CB24: =$Q24-$U24 -> 0 | CC24: =$X24-$AB24 -> 0
A25: ='raw data'!D25 -> bto | B25: ='raw data'!F25 -> 10.085 | C25: =MAX('raw data'!G25:P25) -> 10.189 | D25: =MIN('raw data'!H25:Q25) -> 9.91 | E25: =IF($A25="bto",analyze!C25-'raw data'!F25,IF($A25="sto",'raw data'!F25-analyze!D25,0)) -> 0.104 | F25: =IF(B25>0,E25/B25,0) -> 0.010312345 | G25: =MAX('raw data'!R25:V25) -> 9.9619 | H25: =MIN('raw data'!R25:V25) -> 9.61 | I25: =IF(A25="bto",analyze!G25-B25,IF(A25="sto",B25-analyze!H25,0)) -> -0.1231 | J25: =IF(B25>0,I25/B25,0) -> -0.012206247 | K25: ='raw data'!W25 -> 0.1925 | L25: ='raw data'!X25 -> 66.4415 | M25: ='raw data'!Y25 -> 63.1462 | N25: ='raw data'!Z25 -> 71.4631 | O25: ='raw data'!AA25 -> 48.3203 | P25: ='raw data'!AB25 -> 86.006 | Q25: ='raw data'!AC25 -> 0.8029 | R25: ='raw data'!AD25 -> 0.5496 | ... BI25: ='raw data'!BU25 -> -228.433 | CA25: =$L25-$P25 -> -19.5645 | CB25: =$Q25-$U25 -> 0.3144 | CC25: =$X25-$AB25 -> 0.5321 | CD25: =BF25-BH25 -> 316.4863 | CE25: =AZ25-BA25 -> -0.74
A26: ='raw data'!D26 -> Sell to Close | B26: ='raw data'!F26 -> 10.07 | C26: =MAX('raw data'!G26:P26) -> 38706.406 | D26: =MIN('raw data'!H26:Q26) -> -0.02 | E26: =IF($A26="bto",analyze!C26-'raw data'!F26,IF($A26="sto",'raw data'!F26-analyze!D26,0)) -> 0 | F26: =IF(B26>0,E26/B26,0) -> 0 | G26: =MAX('raw data'!R26:V26) -> 0 | H26: =MIN('raw data'!R26:V26) -> 0 | I26: =IF(A26="bto",analyze!G26-B26,IF(A26="sto",B26-analyze!H26,0)) -> 0 | J26: =IF(B26>0,I26/B26,0) -> 0 | K26: ='raw data'!W26 -> 0 | L26: ='raw data'!X26 -> 0 | M26: ='raw data'!Y26 -> 0 | N26: ='raw data'!Z26 -> 0 | O26: ='raw data'!AA26 -> 0 | P26: ='raw data'!AB26 -> 0 | Q26: ='raw data'!AC26 -> 0 | R26: ='raw data'!AD26 -> 0 | ... BI26: ='raw data'!BU26 -> 0 | CA26: =$L26-$P26 -> 0 | CB26: =$Q26-$U26 -> 0 | CC26: =$X26-$AB26 -> 0
A27: ='raw data'!D27 -> sto | B27: ='raw data'!F27 -> 9.915 | C27: =MAX('raw data'!G27:P27) -> 9.99 | D27: =MIN('raw data'!H27:Q27) -> 9.8881 | E27: =IF($A27="bto",analyze!C27-'raw data'!F27,IF($A27="sto",'raw data'!F27-analyze!D27,0)) -> 0.0269 | F27: =IF(B27>0,E27/B27,0) -> 0.002713061 | G27: =MAX('raw data'!R27:V27) -> 9.91 | H27: =MIN('raw data'!R27:V27) -> 9.6173 | I27: =IF(A27="bto",analyze!G27-B27,IF(A27="sto",B27-analyze!H27,0)) -> 0.2977 | J27: =IF(B27>0,I27/B27,0) -> 0.030025214 | K27: ='raw data'!W27 -> 0.7289 | L27: ='raw data'!X27 -> 24.7344 | M27: ='raw data'!Y27 -> 42.7194 | N27: ='raw data'!Z27 -> 51.7952 | O27: ='raw data'!AA27 -> 66.4415 | P27: ='raw data'!AB27 -> 86.1344 | Q27: ='raw data'!AC27 -> 0.0319 | R27: ='raw data'!AD27 -> 0.6125 | ... BI27: ='raw data'!BU27 -> -243.2238 | CA27: =$L27-$P27 -> -61.4 | CB27: =$Q27-$U27 -> -0.3037 | CC27: =$X27-$AB27 -> -0.9704
A28: ='raw data'!D28 -> Buy to Close | B28: ='raw data'!F28 -> 9.96 | C28: =MAX('raw data'!G28:P28) -> 38706.409 | D28: =MIN('raw data'!H28:Q28) -> -0.04 | E28: =IF($A28="bto",analyze!C28-'raw data'!F28,IF($A28="sto",'raw data'!F28-analyze!D28,0)) -> 0 | F28: =IF(B28>0,E28/B28,0) -> 0 | G28: =MAX('raw data'!R28:V28) -> 0 | H28: =MIN('raw data'!R28:V28) -> 0 | I28: =IF(A28="bto",analyze!G28-B28,IF(A28="sto",B28-analyze!H28,0)) -> 0 | J28: =IF(B28>0,I28/B28,0) -> 0 | K28: ='raw data'!W28 -> 0 | L28: ='raw data'!X28 -> 0 | M28: ='raw data'!Y28 -> 0 | N28: ='raw data'!Z28 -> 0 | O28: ='raw data'!AA28 -> 0 | P28: ='raw data'!AB28 -> 0 | Q28: ='raw data'!AC28 -> 0 | R28: ='raw data'!AD28 -> 0 | ... BI28: ='raw data'!BU28 -> 0 | CA28: =$L28-$P28 -> 0 | CB28: =$Q28-$U28 -> 0 | CC28: =$X28-$AB28 -> 0
A29: ='raw data'!D29 -> sto | B29: ='raw data'!F29 -> 9.9 | C29: =MAX('raw data'!G29:P29) -> 10.0206 | D29: =MIN('raw data'!H29:Q29) -> 9.8881 | E29: =IF($A29="bto",analyze!C29-'raw data'!F29,IF($A29="sto",'raw data'!F29-analyze!D29,0)) -> 0.0119 | F29: =IF(B29>0,E29/B29,0) -> 0.0012020202 | G29: =MAX('raw data'!R29:V29) -> 9.905 | H29: =MIN('raw data'!R29:V29) -> 9.645 | I29: =IF(A29="bto",analyze!G29-B29,IF(A29="sto",B29-analyze!H29,0)) -> 0.255 | J29: =IF(B29>0,I29/B29,0) -> 0.025757576 | K29: ='raw data'!W29 -> 0.4094 | L29: ='raw data'!X29 -> 30.2512 | M29: ='raw data'!Y29 -> 37.0212 | N29: ='raw data'!Z29 -> 42.7194 | O29: ='raw data'!AA29 -> 67.5478 | P29: ='raw data'!AB29 -> 63.1462 | Q29: ='raw data'!AC29 -> -0.3464 | R29: ='raw data'!AD29 -> -0.093 | ... BI29: ='raw data'!BU29 -> -243.4527 | CA29: =$L29-$P29 -> -32.895 | CB29: =$Q29-$U29 -> -0.896 | CC29: =$X29-$AB29 -> -1.2874
A30: ='raw data'!D30 -> Buy to Close | B30: ='raw data'!F30 -> 10.01 | C30: =MAX('raw data'!G30:P30) -> 38706.415 | D30: =MIN('raw data'!H30:Q30) -> -0.11 | E30: =IF($A30="bto",analyze!C30-'raw data'!F30,IF($A30="sto",'raw data'!F30-analyze!D30,0)) -> 0 | F30: =IF(B30>0,E30/B30,0) -> 0 | G30: =MAX('raw data'!R30:V30) -> 0 | H30: =MIN('raw data'!R30:V30) -> 0 | I30: =IF(A30="bto",analyze!G30-B30,IF(A30="sto",B30-analyze!H30,0)) -> 0 | J30: =IF(B30>0,I30/B30,0) -> 0 | K30: ='raw data'!W30 -> 0 | L30: ='raw data'!X30 -> 0 | M30: ='raw data'!Y30 -> 0 | N30: ='raw data'!Z30 -> 0 | O30: ='raw data'!AA30 -> 0 | P30: ='raw data'!AB30 -> 0 | Q30: ='raw data'!AC30 -> 0 | R30: ='raw data'!AD30 -> 0 | ... BI30: ='raw data'!BU30 -> 0 | CA30: =$L30-$P30 -> 0 | CB30: =$Q30-$U30 -> 0 | CC30: =$X30-$AB30 -> 0
A31: ='raw data'!D31 -> sto | B31: ='raw data'!F31 -> 9.7099 | C31: =MAX('raw data'!G31:P31) -> 9.7481 | D31: =MIN('raw data'!H31:Q31) -> 9.7 | E31: =IF($A31="bto",analyze!C31-'raw data'!F31,IF($A31="sto",'raw data'!F31-analyze!D31,0)) -> 0.0099 | F31: =IF(B31>0,E31/B31,0) -> 0.001019578 | G31: =MAX('raw data'!R31:V31) -> 9.7422 | H31: =MIN('raw data'!R31:V31) -> 9.2019 | I31: =IF(A31="bto",analyze!G31-B31,IF(A31="sto",B31-analyze!H31,0)) -> 0.508 | J31: =IF(B31>0,I31/B31,0) -> 0.052317738 | K31: ='raw data'!W31 -> 0.5502 | L31: ='raw data'!X31 -> 25.3325 | M31: ='raw data'!Y31 -> 34.734 | N31: ='raw data'!Z31 -> 44.512 | O31: ='raw data'!AA31 -> 55.1319 | P31: ='raw data'!AB31 -> 40.5768 | Q31: ='raw data'!AC31 -> -3.4084 | R31: ='raw data'!AD31 -> -3.0123 | ... BI31: ='raw data'!BU31 -> -11.3702 | CA31: =$L31-$P31 -> -15.2443 | CB31: =$Q31-$U31 -> -0.5836 | CC31: =$X31-$AB31 -> -0.536
A32: ='raw data'!D32 -> Buy to Close | B32: ='raw data'!F32 -> 9.7 | C32: =MAX('raw data'!G32:P32) -> 38706.508 | D32: =MIN('raw data'!H32:Q32) -> 0 | E32: =IF($A32="bto",analyze!C32-'raw data'!F32,IF($A32="sto",'raw data'!F32-analyze!D32,0)) -> 0 | F32: =IF(B32>0,E32/B32,0) -> 0 | G32: =MAX('raw data'!R32:V32) -> 0 | H32: =MIN('raw data'!R32:V32) -> 0 | I32: =IF(A32="bto",analyze!G32-B32,IF(A32="sto",B32-analyze!H32,0)) -> 0 | J32: =IF(B32>0,I32/B32,0) -> 0 | K32: ='raw data'!W32 -> 0 | L32: ='raw data'!X32 -> 0 | M32: ='raw data'!Y32 -> 0 | N32: ='raw data'!Z32 -> 0 | O32: ='raw data'!AA32 -> 0 | P32: ='raw data'!AB32 -> 0 | Q32: ='raw data'!AC32 -> 0 | R32: ='raw data'!AD32 -> 0 | ... BI32: ='raw data'!BU32 -> 0 | CA32: =$L32-$P32 -> 0 | CB32: =$Q32-$U32 -> 0 | CC32: =$X32-$AB32 -> 0
A33: ='raw data'!D33 -> sto | B33: ='raw data'!F33 -> 9.71 | C33: =MAX('raw data'!G33:P33) -> 9.72 | D33: =MIN('raw data'!H33:Q33) -> 9.685 | E33: =IF($A33="bto",analyze!C33-'raw data'!F33,IF($A33="sto",'raw data'!F33-analyze!D33,0)) -> 0.025 | F33: =IF(B33>0,E33/B33,0) -> 0.0025746653 | G33: =MAX('raw data'!R33:V33) -> 9.675 | H33: =MIN('raw data'!R33:V33) -> 8.9 | I33: =IF(A33="bto",analyze!G33-B33,IF(A33="sto",B33-analyze!H33,0)) -> 0.81 | J33: =IF(B33>0,I33/B33,0) -> 0.083419156 | K33: ='raw data'!W33 -> 0.4593 | L33: ='raw data'!X33 -> 29.5576 | M33: ='raw data'!Y33 -> 39.6394 | N33: ='raw data'!Z33 -> 28.1179 | O33: ='raw data'!AA33 -> 47.8232 | P33: ='raw data'!AB33 -> 51.385 | Q33: ='raw data'!AC33 -> -4.3505 | R33: ='raw data'!AD33 -> -4.0585 | ... BI33: ='raw data'!BU33 -> -24.6646 | CA33: =$L33-$P33 -> -21.8274 | CB33: =$Q33-$U33 -> -0.9939 | CC33: =$X33-$AB33 -> -0.4365
A34: ='raw data'!D34 -> Buy to Close | B34: ='raw data'!F34 -> 9.72 | C34: =MAX('raw data'!G34:P34) -> 38706.553 | D34: =MIN('raw data'!H34:Q34) -> -0.01 | E34: =IF($A34="bto",analyze!C34-'raw data'!F34,IF($A34="sto",'raw data'!F34-analyze!D34,0)) -> 0 | F34: =IF(B34>0,E34/B34,0) -> 0 | G34: =MAX('raw data'!R34:V34) -> 0 | H34: =MIN('raw data'!R34:V34) -> 0 | I34: =IF(A34="bto",analyze!G34-B34,IF(A34="sto",B34-analyze!H34,0)) -> 0 | J34: =IF(B34>0,I34/B34,0) -> 0 | K34: ='raw data'!W34 -> 0 | L34: ='raw data'!X34 -> 0 | M34: ='raw data'!Y34 -> 0 | N34: ='raw data'!Z34 -> 0 | O34: ='raw data'!AA34 -> 0 | P34: ='raw data'!AB34 -> 0 | Q34: ='raw data'!AC34 -> 0 | R34: ='raw data'!AD34 -> 0 | ... BI34: ='raw data'!BU34 -> 0 | CA34: =$L34-$P34 -> 0 | CB34: =$Q34-$U34 -> 0 | CC34: =$X34-$AB34 -> 0
A35: ='raw data'!D35 -> bto | B35: ='raw data'!F35 -> 9.47 | C35: =MAX('raw data'!G35:P35) -> 9.495 | D35: =MIN('raw data'!H35:Q35) -> 9.2981 | E35: =IF($A35="bto",analyze!C35-'raw data'!F35,IF($A35="sto",'raw data'!F35-analyze!D35,0)) -> 0.025 | F35: =IF(B35>0,E35/B35,0) -> 0.0026399155 | G35: =MAX('raw data'!R35:V35) -> 9.3399 | H35: =MIN('raw data'!R35:V35) -> 8.956 | I35: =IF(A35="bto",analyze!G35-B35,IF(A35="sto",B35-analyze!H35,0)) -> -0.1301 | J35: =IF(B35>0,I35/B35,0) -> -0.01373812 | K35: ='raw data'!W35 -> 0.29 | L35: ='raw data'!X35 -> 66.4564 | M35: ='raw data'!Y35 -> 59.718 | N35: ='raw data'!Z35 -> 57.8445 | O35: ='raw data'!AA35 -> 53.7845 | P35: ='raw data'!AB35 -> 52.938 | Q35: ='raw data'!AC35 -> -0.9855 | R35: ='raw data'!AD35 -> -1.2297 | ... BI35: ='raw data'!BU35 -> -179.0754 | CA35: =$L35-$P35 -> 13.5184 | CB35: =$Q35-$U35 -> 0.4609 | CC35: =$X35-$AB35 -> 0.6133 | CD35: =BF35-BH35 -> -4.37 | CE35: =AZ35-BA35 -> 0.52
A36: ='raw data'!D36 -> Sell to Close | B36: ='raw data'!F36 -> 9.35 | C36: =MAX('raw data'!G36:P36) -> 0 | D36: =MIN('raw data'!H36:Q36) -> -0.12 | E36: =IF($A36="bto",analyze!C36-'raw data'!F36,IF($A36="sto",'raw data'!F36-analyze!D36,0)) -> 0 | F36: =IF(B36>0,E36/B36,0) -> 0 | G36: =MAX('raw data'!R36:V36) -> 0 | H36: =MIN('raw data'!R36:V36) -> 0 | I36: =IF(A36="bto",analyze!G36-B36,IF(A36="sto",B36-analyze!H36,0)) -> 0 | J36: =IF(B36>0,I36/B36,0) -> 0 | K36: ='raw data'!W36 -> 0 | L36: ='raw data'!X36 -> 0 | M36: ='raw data'!Y36 -> 0 | N36: ='raw data'!Z36 -> 0 | O36: ='raw data'!AA36 -> 0 | P36: ='raw data'!AB36 -> 0 | Q36: ='raw data'!AC36 -> 0 | R36: ='raw data'!AD36 -> 0 | ... BI36: ='raw data'!BU36 -> 0 | CA36: =$L36-$P36 -> 0 | CB36: =$Q36-$U36 -> 0 | CC36: =$X36-$AB36 -> 0
A37: ='raw data'!D37 -> sto | B37: ='raw data'!F37 -> 9.205 | C37: =MAX('raw data'!G37:P37) -> 9.31 | D37: =MIN('raw data'!H37:Q37) -> 9.17 | E37: =IF($A37="bto",analyze!C37-'raw data'!F37,IF($A37="sto",'raw data'!F37-analyze!D37,0)) -> 0.035 | F37: =IF(B37>0,E37/B37,0) -> 0.0038022814 | G37: =MAX('raw data'!R37:V37) -> 9.1715 | H37: =MIN('raw data'!R37:V37) -> 9.0152 | I37: =IF(A37="bto",analyze!G37-B37,IF(A37="sto",B37-analyze!H37,0)) -> 0.1898 | J37: =IF(B37>0,I37/B37,0) -> 0.020619229 | K37: ='raw data'!W37 -> 0.6881 | L37: ='raw data'!X37 -> 21.7193 | M37: ='raw data'!Y37 -> 28.5365 | N37: ='raw data'!Z37 -> 56.0342 | O37: ='raw data'!AA37 -> 53.194 | P37: ='raw data'!AB37 -> 45.8601 | Q37: ='raw data'!AC37 -> -2.389 | R37: ='raw data'!AD37 -> -1.9454 | ... BI37: ='raw data'!BU37 -> -35.7039 | CA37: =$L37-$P37 -> -24.1408 | CB37: =$Q37-$U37 -> -0.9712 | CC37: =$X37-$AB37 -> -1.1782
A38: ='raw data'!D38 -> Buy to Close | B38: ='raw data'!F38 -> 9.3 | C38: =MAX('raw data'!G38:P38) -> 0 | D38: =MIN('raw data'!H38:Q38) -> -0.22 | E38: =IF($A38="bto",analyze!C38-'raw data'!F38,IF($A38="sto",'raw data'!F38-analyze!D38,0)) -> 0 | F38: =IF(B38>0,E38/B38,0) -> 0 | G38: =MAX('raw data'!R38:V38) -> 0 | H38: =MIN('raw data'!R38:V38) -> 0 | I38: =IF(A38="bto",analyze!G38-B38,IF(A38="sto",B38-analyze!H38,0)) -> 0 | J38: =IF(B38>0,I38/B38,0) -> 0 | K38: ='raw data'!W38 -> 0 | L38: ='raw data'!X38 -> 0 | M38: ='raw data'!Y38 -> 0 | N38: ='raw data'!Z38 -> 0 | O38: ='raw data'!AA38 -> 0 | P38: ='raw data'!AB38 -> 0 | Q38: ='raw data'!AC38 -> 0 | R38: ='raw data'!AD38 -> 0 | ... BI38: ='raw data'!BU38 -> 0 | CA38: =$L38-$P38 -> 0 | CB38: =$Q38-$U38 -> 0 | CC38: =$X38-$AB38 -> 0
A39: ='raw data'!D39 -> sto | B39: ='raw data'!F39 -> 9.165 | C39: =MAX('raw data'!G39:P39) -> 9.2199 | D39: =MIN('raw data'!H39:Q39) -> 9.1581 | E39: =IF($A39="bto",analyze!C39-'raw data'!F39,IF($A39="sto",'raw data'!F39-analyze!D39,0)) -> 0.0069 | F39: =IF(B39>0,E39/B39,0) -> 0.00075286416 | G39: =MAX('raw data'!R39:V39) -> 9.175 | H39: =MIN('raw data'!R39:V39) -> 8.91 | I39: =IF(A39="bto",analyze!G39-B39,IF(A39="sto",B39-analyze!H39,0)) -> 0.255 | J39: =IF(B39>0,I39/B39,0) -> 0.027823241 | K39: ='raw data'!W39 -> 0.8257 | L39: ='raw data'!X39 -> 29.8441 | M39: ='raw data'!Y39 -> 34.9261 | N39: ='raw data'!Z39 -> 52.4102 | O39: ='raw data'!AA39 -> 43.0294 | P39: ='raw data'!AB39 -> 21.7193 | Q39: ='raw data'!AC39 -> -3.2954 | R39: ='raw data'!AD39 -> -2.9907 | ... BI39: ='raw data'!BU39 -> -78.6041 | CA39: =$L39-$P39 -> 8.1248 | CB39: =$Q39-$U39 -> -0.9064 | CC39: =$X39-$AB39 -> -0.7515
A40: ='raw data'!D40 -> Buy to Close | B40: ='raw data'!F40 -> 9.16 | C40: =MAX('raw data'!G40:P40) -> 0 | D40: =MIN('raw data'!H40:Q40) -> -0.22 | E40: =IF($A40="bto",analyze!C40-'raw data'!F40,IF($A40="sto",'raw data'!F40-analyze!D40,0)) -> 0 | F40: =IF(B40>0,E40/B40,0) -> 0 | G40: =MAX('raw data'!R40:V40) -> 0 | H40: =MIN('raw data'!R40:V40) -> 0 | I40: =IF(A40="bto",analyze!G40-B40,IF(A40="sto",B40-analyze!H40,0)) -> 0 | J40: =IF(B40>0,I40/B40,0) -> 0 | K40: ='raw data'!W40 -> 0 | L40: ='raw data'!X40 -> 0 | M40: ='raw data'!Y40 -> 0 | N40: ='raw data'!Z40 -> 0 | O40: ='raw data'!AA40 -> 0 | P40: ='raw data'!AB40 -> 0 | Q40: ='raw data'!AC40 -> 0 | R40: ='raw data'!AD40 -> 0 | ... BI40: ='raw data'!BU40 -> 0 | CA40: =$L40-$P40 -> 0 | CB40: =$Q40-$U40 -> 0 | CC40: =$X40-$AB40 -> 0
A41: ='raw data'!D41 -> sto | B41: ='raw data'!F41 -> 9.1645 | C41: =MAX('raw data'!G41:P41) -> 9.205 | D41: =MIN('raw data'!H41:Q41) -> 9.1581 | E41: =IF($A41="bto",analyze!C41-'raw data'!F41,IF($A41="sto",'raw data'!F41-analyze!D41,0)) -> 0.0064 | F41: =IF(B41>0,E41/B41,0) -> 0.00069834688 | G41: =MAX('raw data'!R41:V41) -> 9.12 | H41: =MIN('raw data'!R41:V41) -> 8.97 | I41: =IF(A41="bto",analyze!G41-B41,IF(A41="sto",B41-analyze!H41,0)) -> 0.1945 | J41: =IF(B41>0,I41/B41,0) -> 0.021223198 | K41: ='raw data'!W41 -> 0.2831 | L41: ='raw data'!X41 -> 36.1629 | M41: ='raw data'!Y41 -> 46.7648 | N41: ='raw data'!Z41 -> 34.9261 | O41: ='raw data'!AA41 -> 57.5242 | P41: ='raw data'!AB41 -> 27.4761 | Q41: ='raw data'!AC41 -> -3.1981 | R41: ='raw data'!AD41 -> -2.7204 | ... BI41: ='raw data'!BU41 -> -84.1472 | CA41: =$L41-$P41 -> 8.6868 | CB41: =$Q41-$U41 -> -0.5164 | CC41: =$X41-$AB41 -> -0.8279
A42: ='raw data'!D42 -> Buy to Close | B42: ='raw data'!F42 -> 9.19 | C42: =MAX('raw data'!G42:P42) -> 0 | D42: =MIN('raw data'!H42:Q42) -> -0.24 | E42: =IF($A42="bto",analyze!C42-'raw data'!F42,IF($A42="sto",'raw data'!F42-analyze!D42,0)) -> 0 | F42: =IF(B42>0,E42/B42,0) -> 0 | G42: =MAX('raw data'!R42:V42) -> 0 | H42: =MIN('raw data'!R42:V42) -> 0 | I42: =IF(A42="bto",analyze!G42-B42,IF(A42="sto",B42-analyze!H42,0)) -> 0 | J42: =IF(B42>0,I42/B42,0) -> 0 | K42: ='raw data'!W42 -> 0 | L42: ='raw data'!X42 -> 0 | M42: ='raw data'!Y42 -> 0 | N42: ='raw data'!Z42 -> 0 | O42: ='raw data'!AA42 -> 0 | P42: ='raw data'!AB42 -> 0 | Q42: ='raw data'!AC42 -> 0 | R42: ='raw data'!AD42 -> 0 | ... BI42: ='raw data'!BU42 -> 0 | CA42: =$L42-$P42 -> 0 | CB42: =$Q42-$U42 -> 0 | CC42: =$X42-$AB42 -> 0
A43: ='raw data'!D43 -> sto | B43: ='raw data'!F43 -> 8.98 | C43: =MAX('raw data'!G43:P43) -> 8.9783 | D43: =MIN('raw data'!H43:Q43) -> 8.915 | E43: =IF($A43="bto",analyze!C43-'raw data'!F43,IF($A43="sto",'raw data'!F43-analyze!D43,0)) -> 0.065 | F43: =IF(B43>0,E43/B43,0) -> 0.0072383073 | G43: =MAX('raw data'!R43:V43) -> 9.07 | H43: =MIN('raw data'!R43:V43) -> 8.6481 | I43: =IF(A43="bto",analyze!G43-B43,IF(A43="sto",B43-analyze!H43,0)) -> 0.3319 | J43: =IF(B43>0,I43/B43,0) -> 0.036959911 | K43: ='raw data'!W43 -> 0.2108 | L43: ='raw data'!X43 -> 47.414 | M43: ='raw data'!Y43 -> 56.8618 | N43: ='raw data'!Z43 -> 72.9562 | O43: ='raw data'!AA43 -> 70.3029 | P43: ='raw data'!AB43 -> 42.3397 | Q43: ='raw data'!AC43 -> -7.803 | R43: ='raw data'!AD43 -> -7.6214 | ... BI43: ='raw data'!BU43 -> -221.8385 | CA43: =$L43-$P43 -> 5.0743 | CB43: =$Q43-$U43 -> 0.0645 | CC43: =$X43-$AB43 -> 1.5205
A44: ='raw data'!D44 -> Buy to Close | B44: ='raw data'!F44 -> 8.98 | C44: =MAX('raw data'!G44:P44) -> 0 | D44: =MIN('raw data'!H44:Q44) -> -0.24 | E44: =IF($A44="bto",analyze!C44-'raw data'!F44,IF($A44="sto",'raw data'!F44-analyze!D44,0)) -> 0 | F44: =IF(B44>0,E44/B44,0) -> 0 | G44: =MAX('raw data'!R44:V44) -> 0 | H44: =MIN('raw data'!R44:V44) -> 0 | I44: =IF(A44="bto",analyze!G44-B44,IF(A44="sto",B44-analyze!H44,0)) -> 0 | J44: =IF(B44>0,I44/B44,0) -> 0 | K44: ='raw data'!W44 -> 0 | L44: ='raw data'!X44 -> 0 | M44: ='raw data'!Y44 -> 0 | N44: ='raw data'!Z44 -> 0 | O44: ='raw data'!AA44 -> 0 | P44: ='raw data'!AB44 -> 0 | Q44: ='raw data'!AC44 -> 0 | R44: ='raw data'!AD44 -> 0 | ... BI44: ='raw data'!BU44 -> 0 | CA44: =$L44-$P44 -> 0 | CB44: =$Q44-$U44 -> 0 | CC44: =$X44-$AB44 -> 0
A45: ='raw data'!D45 -> sto | B45: ='raw data'!F45 -> 9 | C45: =MAX('raw data'!G45:P45) -> 9.05 | D45: =MIN('raw data'!H45:Q45) -> 8.955 | E45: =IF($A45="bto",analyze!C45-'raw data'!F45,IF($A45="sto",'raw data'!F45-analyze!D45,0)) -> 0.045 | F45: =IF(B45>0,E45/B45,0) -> 0.005 | G45: =MAX('raw data'!R45:V45) -> 9.1194 | H45: =MIN('raw data'!R45:V45) -> 8.6741 | I45: =IF(A45="bto",analyze!G45-B45,IF(A45="sto",B45-analyze!H45,0)) -> 0.3259 | J45: =IF(B45>0,I45/B45,0) -> 0.036211111 | K45: ='raw data'!W45 -> 0.2788 | L45: ='raw data'!X45 -> 42.2571 | M45: ='raw data'!Y45 -> 47.6387 | N45: ='raw data'!Z45 -> 62.4812 | O45: ='raw data'!AA45 -> 67.9249 | P45: ='raw data'!AB45 -> 68.0479 | Q45: ='raw data'!AC45 -> -8.5278 | R45: ='raw data'!AD45 -> -8.4815 | ... BI45: ='raw data'!BU45 -> -311.3578 | CA45: =$L45-$P45 -> -25.7908 | CB45: =$Q45-$U45 -> -0.3249 | CC45: =$X45-$AB45 -> -0.4014
...

Sheet cs sto
A1: =analyze!A1 -> sto/bto | B1: =analyze!B1 -> price | C1: =analyze!C1 -> short-term max | D1: =analyze!D1 -> short-term min | E1: =analyze!E1 -> short-term success | F1: =analyze!F1 -> STS % | G1: =analyze!G1 -> long-term max | H1: =analyze!H1 -> short-term min | ... AT1: =analyze!AT1 -> adc[5] | AU1: =analyze!CA1 -> drsi | AV1: =analyze!CB1 -> ddvi | AW1: =analyze!CC1 -> drs
A2: =analyze!A2 -> 0 | B2: =analyze!B2 -> 0 | C2: =analyze!C2 -> 0 | D2: =analyze!D2 -> 0 | E2: =analyze!E2 -> 0 | F2: =analyze!F2 -> 0 | G2: =analyze!G2 -> 0 | H2: =analyze!H2 -> 0 | ... AT2: =analyze!AT2 -> 0 | AU2: =analyze!CA2 -> 0 | AV2: =analyze!CB2 -> 0 | AW2: =analyze!CC2 -> 0
A3: =analyze!A3 -> 0 | B3: =analyze!B3 -> 0 | C3: =analyze!C3 -> 0 | D3: =analyze!D3 -> 0 | E3: =analyze!E3 -> 0 | F3: =analyze!F3 -> 0 | G3: =analyze!G3 -> 0 | H3: =analyze!H3 -> 0 | ... AT3: =analyze!AT3 -> 0 | AU3: =analyze!CA3 -> 0 | AV3: =analyze!CB3 -> 0 | AW3: =analyze!CC3 -> 0
A4: =analyze!A4 -> 0 | B4: =analyze!B4 -> 0 | C4: =analyze!C4 -> 0 | D4: =analyze!D4 -> 0 | E4: =analyze!E4 -> 0 | F4: =analyze!F4 -> 0 | G4: =analyze!G4 -> 0 | H4: =analyze!H4 -> 0 | ... AT4: =analyze!AT4 -> 0 | AU4: =analyze!CA4 -> 0 | AV4: =analyze!CB4 -> 0 | AW4: =analyze!CC4 -> 0
A5: =analyze!A5 -> 0 | B5: =analyze!B5 -> 0 | C5: =analyze!C5 -> 0 | D5: =analyze!D5 -> 0 | E5: =analyze!E5 -> 0 | F5: =analyze!F5 -> 0 | G5: =analyze!G5 -> 0 | H5: =analyze!H5 -> 0 | ... AT5: =analyze!AT5 -> 0 | AU5: =analyze!CA5 -> 0 | AV5: =analyze!CB5 -> 0 | AW5: =analyze!CC5 -> 0
A6: =analyze!A6 -> 0 | B6: =analyze!B6 -> 0 | C6: =analyze!C6 -> 0 | D6: =analyze!D6 -> 0 | E6: =analyze!E6 -> 0 | F6: =analyze!F6 -> 0 | G6: =analyze!G6 -> 0 | H6: =analyze!H6 -> 0 | ... AT6: =analyze!AT6 -> 0 | AU6: =analyze!CA6 -> 0 | AV6: =analyze!CB6 -> 0 | AW6: =analyze!CC6 -> 0
A7: =analyze!A7 -> bto | B7: =analyze!B7 -> 9.82 | C7: =analyze!C7 -> 9.8 | D7: =analyze!D7 -> 9.725 | E7: =analyze!E7 -> -0.02 | F7: =analyze!F7 -> -0.0020366599 | G7: =analyze!G7 -> 10.085 | H7: =analyze!H7 -> 9.7381 | ... AT7: =analyze!AT7 -> 46.6396 | AU7: =analyze!CA7 -> 8.7925 | AV7: =analyze!CB7 -> -0.0478 | AW7: =analyze!CC7 -> 0.4543
A8: =analyze!A8 -> Sell to Close | B8: =analyze!B8 -> 9.73 | C8: =analyze!C8 -> 38676.417 | D8: =analyze!D8 -> -0.1 | E8: =analyze!E8 -> 0 | F8: =analyze!F8 -> 0 | G8: =analyze!G8 -> 0 | H8: =analyze!H8 -> 0 | ... AT8: =analyze!AT8 -> 0 | AU8: =analyze!CA8 -> 0 | AV8: =analyze!CB8 -> 0 | AW8: =analyze!CC8 -> 0
A9: =analyze!A9 -> bto | B9: =analyze!B9 -> 9.821 | C9: =analyze!C9 -> 9.835 | D9: =analyze!D9 -> 9.81 | E9: =analyze!E9 -> 0.014 | F9: =analyze!F9 -> 0.0014255167 | G9: =analyze!G9 -> 10.1419 | H9: =analyze!H9 -> 9.771 | ... AT9: =analyze!AT9 -> 12.8436 | AU9: =analyze!CA9 -> 14.8515 | AV9: =analyze!CB9 -> 0.1996 | AW9: =analyze!CC9 -> 0.5107
A10: =analyze!A10 -> Sell to Close | B10: =analyze!B10 -> 9.82 | C10: =analyze!C10 -> 38676.465 | D10: =analyze!D10 -> -0.1 | E10: =analyze!E10 -> 0 | F10: =analyze!F10 -> 0 | G10: =analyze!G10 -> 0 | H10: =analyze!H10 -> 0 | ... AT10: =analyze!AT10 -> 0 | AU10: =analyze!CA10 -> 0 | AV10: =analyze!CB10 -> 0 | AW10: =analyze!CC10 -> 0
A11: =analyze!A11 -> bto | B11: =analyze!B11 -> 9.85 | C11: =analyze!C11 -> 9.9199 | D11: =analyze!D11 -> 9.85 | E11: =analyze!E11 -> 0.0699 | F11: =analyze!F11 -> 0.0070964467 | G11: =analyze!G11 -> 10.16 | H11: =analyze!H11 -> 9.9481 | ... AT11: =analyze!AT11 -> 21.5849 | AU11: =analyze!CA11 -> 16.2325 | AV11: =analyze!CB11 -> 0.2542 | AW11: =analyze!CC11 -> 0.3951
A12: =analyze!A12 -> Sell to Close | B12: =analyze!B12 -> 9.85 | C12: =analyze!C12 -> 38676.483 | D12: =analyze!D12 -> -0.1 | E12: =analyze!E12 -> 0 | F12: =analyze!F12 -> 0 | G12: =analyze!G12 -> 0 | H12: =analyze!H12 -> 0 | ... AT12: =analyze!AT12 -> 0 | AU12: =analyze!CA12 -> 0 | AV12: =analyze!CB12 -> 0 | AW12: =analyze!CC12 -> 0
... A402: =analyze!A402 -> 0 | B402: =analyze!B402 -> 0 | C402: =analyze!C402 -> 0 | D402: =analyze!D402 -> 0 | E402: =analyze!E402 -> 0 | F402: =analyze!F402 -> 0 | G402: =analyze!G402 -> 0 | H402: =analyze!H402 -> 0 | ... AT402: =analyze!AT402 -> 0 | AU402: =analyze!CA402 -> 0 | AV402: =analyze!CB402 -> 0 | AW402: =analyze!CC402 -> 0
C446: drsi<-8

Sheet raw data
B1: Strategy report
B2: Symbol: AAL
B3: Work Time: 5/11/20 9:45 AM - 5/18/20 2:37 PM
B6: Id | C6: Strategy | D6: Side | E6: Amount | F6: Price | G6: Date/Time | H6: Trade P/L | I6: P/L | J6: Position
